Workbook

Sheet Cover & Instructions
B2: AHQS LABORATORY INSPECTION READINESS TOOLKIT
B3: Accelerate Healthcare Quality Solutions
B4: Independent Healthcare Quality, Accreditation & Laboratory Excellence Support
B6: ══════════════════════════════════════════════════════════════════════════════════════════
B8: PURPOSE
B9: This toolkit provides laboratories with a structured, framework-driven approach to accreditation readiness. It follows the AHQS methodology: Assess → Prioritize → Improve → Sustain. Use it to identify gaps, track corrective actions, organize evidence, and demonstrate sustained compliance across ISO 15189, CAP, JCI, and AABB accreditation pathways.
B11: THE AHQS FRAMEWORK
B12: 1. ASSESS
B13: Evaluate current compliance against accreditation requirements. Score each area as Compliant, Partial, Non-Compliant, or Not Applicable.
B14: 2. PRIORITIZE
B15: Identify gaps and assess risk using severity and likelihood scoring. Focus on high-risk areas first.
B16: 3. IMPROVE
... B39: DISCLAIMER

Sheet Executive Summary
B2: EXECUTIVE SUMMARY
B3: Laboratory Inspection Readiness — Leadership Overview
B5: Organization: | C5: ='Assessment Setup'!C5 -> 0
B6: Laboratory/Site: | C6: ='Assessment Setup'!C6 -> 0
B7: Assessment Date: | C7: ='Assessment Setup'!C9 -> 0
B8: Target Standard(s): | C8: ='Assessment Setup'!C11 -> ISO 15189 / CAP / JCI / AABB
B10: KEY READINESS METRICS
B11: Total Audit Items | C11: =COUNTA('Master Audit Tool'!B5:B151) -> 147
B12: Compliant Items | C12: =COUNTIF('Master Audit Tool'!I5:I151,"Compliant") -> 0
B13: Partial Items | C13: =COUNTIF('Master Audit Tool'!I5:I151,"Partial") -> 0
B14: Non-Compliant Items | C14: =COUNTIF('Master Audit Tool'!I5:I151,"Non-Compliant") -> 0
B15: Not Applicable | C15: =COUNTIF('Master Audit Tool'!I5:I151,"Not Applicable") -> 0
B16: Pending Assessment | C16: =COUNTBLANK('Master Audit Tool'!I5:I151) -> 147
B18: OVERALL READINESS SCORE | C18: =IFERROR(AVERAGEIF('Master Audit Tool'!J5:J151,">=0"),0) -> 0
B19: READINESS STATUS | C19: =IF(C18>=0.85,"READY",IF(C18>=0.6,"NEEDS FOCUS","HIGH RISK")) -> HIGH RISK
B21: GAP SUMMARY
B22: Total Gaps Identified: | C22: =COUNTIF('Gap Register'!B5:B34,"GAP-*") -> 30
B23: High-Risk Gaps: | C23: =COUNTIFS('Gap Register'!G5:G34,"High")+COUNTIFS('Gap Register'!G5:G34,"Critical") -> 0
B24: Overdue CAPAs: | C24: =COUNTIF('CAPA Action Plan'!L5:L34,"OVERDUE") -> 0
B26: EXECUTIVE NARRATIVE
B27: Complete the audit tool to generate readiness metrics automatically. The overall readiness score, gap count, and CAPA status will populate here based on the data entered in the Master Audit Tool and Gap Register.

Sheet Dashboard
B2: READINESS DASHBOARD
B4: Compliance Status Distribution | F4: Readiness by Domain
B5: Status | C5: Count | D5: Percentage | F5: Domain | G5: Readiness %
B6: Compliant | C6: =COUNTIF('Master Audit Tool'!I5:I151,"Compliant") -> 0 | D6: =IFERROR(C6/SUM($C$6:$C$10),0) -> 0 | F6: Quality Management System | G6: =IFERROR(SUMIFS('Master Audit Tool'!J5:J151,'Master Audit Tool'!D5:D151,F6,'Master Audit Tool'!J5:J151,">=0")/COUNTIFS('Master Audit Tool'!D5:D151,F6,'Master Audit Tool'!J5:J151,">=0"),0) -> 0
B7: Partial | C7: =COUNTIF('Master Audit Tool'!I5:I151,"Partial") -> 0 | D7: =IFERROR(C7/SUM($C$6:$C$10),0) -> 0 | F7: Document Control | G7: =IFERROR(SUMIFS('Master Audit Tool'!J5:J151,'Master Audit Tool'!D5:D151,F7,'Master Audit Tool'!J5:J151,">=0")/COUNTIFS('Master Audit Tool'!D5:D151,F7,'Master Audit Tool'!J5:J151,">=0"),0) -> 0
B8: Non-Compliant | C8: =COUNTIF('Master Audit Tool'!I5:I151,"Non-Compliant") -> 0 | D8: =IFERROR(C8/SUM($C$6:$C$10),0) -> 0 | F8: Personnel Competency | G8: =IFERROR(SUMIFS('Master Audit Tool'!J5:J151,'Master Audit Tool'!D5:D151,F8,'Master Audit Tool'!J5:J151,">=0")/COUNTIFS('Master Audit Tool'!D5:D151,F8,'Master Audit Tool'!J5:J151,">=0"),0) -> 0
B9: Not Applicable | C9: =COUNTIF('Master Audit Tool'!I5:I151,"Not Applicable") -> 0 | D9: =IFERROR(C9/SUM($C$6:$C$10),0) -> 0 | F9: Equipment & Instrumentation | G9: =IFERROR(SUMIFS('Master Audit Tool'!J5:J151,'Master Audit Tool'!D5:D151,F9,'Master Audit Tool'!J5:J151,">=0")/COUNTIFS('Master Audit Tool'!D5:D151,F9,'Master Audit Tool'!J5:J151,">=0"),0) -> 0
B10: Pending | C10: =COUNTBLANK('Master Audit Tool'!I5:I151) -> 147 | D10: =IFERROR(C10/SUM($C$6:$C$10),0) -> 1 | F10: Method Validation & Verification | G10: =IFERROR(SUMIFS('Master Audit Tool'!J5:J151,'Master Audit Tool'!D5:D151,F10,'Master Audit Tool'!J5:J151,">=0")/COUNTIFS('Master Audit Tool'!D5:D151,F10,'Master Audit Tool'!J5:J151,">=0"),0) -> 0
F11: Sample Management | G11: =IFERROR(SUMIFS('Master Audit Tool'!J5:J151,'Master Audit Tool'!D5:D151,F11,'Master Audit Tool'!J5:J151,">=0")/COUNTIFS('Master Audit Tool'!D5:D151,F11,'Master Audit Tool'!J5:J151,">=0"),0) -> 0
F12: Examination Procedures | G12: =IFERROR(SUMIFS('Master Audit Tool'!J5:J151,'Master Audit Tool'!D5:D151,F12,'Master Audit Tool'!J5:J151,">=0")/COUNTIFS('Master Audit Tool'!D5:D151,F12,'Master Audit Tool'!J5:J151,">=0"),0) -> 0
F13: Quality Control | G13: =IFERROR(SUMIFS('Master Audit Tool'!J5:J151,'Master Audit Tool'!D5:D151,F13,'Master Audit Tool'!J5:J151,">=0")/COUNTIFS('Master Audit Tool'!D5:D151,F13,'Master Audit Tool'!J5:J151,">=0"),0) -> 0
F14: External Quality Assessment (PT/EQA) | G14: =IFERROR(SUMIFS('Master Audit Tool'!J5:J151,'Master Audit Tool'!D5:D151,F14,'Master Audit Tool'!J5:J151,">=0")/COUNTIFS('Master Audit Tool'!D5:D151,F14,'Master Audit Tool'!J5:J151,">=0"),0) -> 0
F15: Information Management (LIS) | G15: =IFERROR(SUMIFS('Master Audit Tool'!J5:J151,'Master Audit Tool'!D5:D151,F15,'Master Audit Tool'!J5:J151,">=0")/COUNTIFS('Master Audit Tool'!D5:D151,F15,'Master Audit Tool'!J5:J151,">=0"),0) -> 0
F16: Facility & Safety | G16: =IFERROR(SUMIFS('Master Audit Tool'!J5:J151,'Master Audit Tool'!D5:D151,F16,'Master Audit Tool'!J5:J151,">=0")/COUNTIFS('Master Audit Tool'!D5:D151,F16,'Master Audit Tool'!J5:J151,">=0"),0) -> 0
F17: Transfusion Medicine | G17: =IFERROR(SUMIFS('Master Audit Tool'!J5:J151,'Master Audit Tool'!D5:D151,F17,'Master Audit Tool'!J5:J151,">=0")/COUNTIFS('Master Audit Tool'!D5:D151,F17,'Master Audit Tool'!J5:J151,">=0"),0) -> 0
F19: OVERALL | G19: =IFERROR(AVERAGEIF('Master Audit Tool'!J5:J151,">=0"),0) -> 0
B25: Gap Severity Distribution | F25: CAPA Status Distribution
B26: Severity | C26: Count | F26: CAPA Status | G26: Count
B27: Critical | C27: =COUNTIF('Gap Register'!G5:G34,"Critical") -> 0 | F27: Not Started | G27: =COUNTIF('CAPA Action Plan'!K5:K34,"Not Started") -> 0
B28: High | C28: =COUNTIF('Gap Register'!G5:G34,"High") -> 0 | F28: In Progress | G28: =COUNTIF('CAPA Action Plan'!K5:K34,"In Progress") -> 0
B29: Medium | C29: =COUNTIF('Gap Register'!G5:G34,"Medium") -> 0 | F29: Complete | G29: =COUNTIF('CAPA Action Plan'!K5:K34,"Complete") -> 0
B30: Low | C30: =COUNTIF('Gap Register'!G5:G34,"Low") -> 0 | F30: Verified | G30: =COUNTIF('CAPA Action Plan'!K5:K34,"Verified") -> 0
F31: Overdue | G31: =COUNTIF('CAPA Action Plan'!K5:K34,"Overdue") -> 0
B33: Domain Risk Heatmap
B34: Domain | C34: Avg Risk Score
B35: Quality Management System | C35: =IFERROR(AVERAGEIFS('Master Audit Tool'!M5:M67,'Master Audit Tool'!D5:D67,B35,'Master Audit Tool'!M5:M67,">0"),0) -> 0
B36: Document Control | C36: =IFERROR(AVERAGEIFS('Master Audit Tool'!M5:M67,'Master Audit Tool'!D5:D67,B36,'Master Audit Tool'!M5:M67,">0"),0) -> 0
B37: Personnel Competency | C37: =IFERROR(AVERAGEIFS('Master Audit Tool'!M5:M67,'Master Audit Tool'!D5:D67,B37,'Master Audit Tool'!M5:M67,">0"),0) -> 0
B38: Equipment & Instrumentation | C38: =IFERROR(AVERAGEIFS('Master Audit Tool'!M5:M67,'Master Audit Tool'!D5:D67,B38,'Master Audit Tool'!M5:M67,">0"),0) -> 0
B39: Method Validation & Verification | C39: =IFERROR(AVERAGEIFS('Master Audit Tool'!M5:M67,'Master Audit Tool'!D5:D67,B39,'Master Audit Tool'!M5:M67,">0"),0) -> 0
B40: Sample Management | C40: =IFERROR(AVERAGEIFS('Master Audit Tool'!M5:M67,'Master Audit Tool'!D5:D67,B40,'Master Audit Tool'!M5:M67,">0"),0) -> 0
B41: Examination Procedures | C41: =IFERROR(AVERAGEIFS('Master Audit Tool'!M5:M67,'Master Audit Tool'!D5:D67,B41,'Master Audit Tool'!M5:M67,">0"),0) -> 0
B42: Quality Control | C42: =IFERROR(AVERAGEIFS('Master Audit Tool'!M5:M67,'Master Audit Tool'!D5:D67,B42,'Master Audit Tool'!M5:M67,">0"),0) -> 0
B43: External Quality Assessment (PT/EQA) | C43: =IFERROR(AVERAGEIFS('Master Audit Tool'!M5:M67,'Master Audit Tool'!D5:D67,B43,'Master Audit Tool'!M5:M67,">0"),0) -> 0
B44: Information Management (LIS) | C44: =IFERROR(AVERAGEIFS('Master Audit Tool'!M5:M67,'Master Audit Tool'!D5:D67,B44,'Master Audit Tool'!M5:M67,">0"),0) -> 0
B45: Facility & Safety | C45: =IFERROR(AVERAGEIFS('Master Audit Tool'!M5:M67,'Master Audit Tool'!D5:D67,B45,'Master Audit Tool'!M5:M67,">0"),0) -> 0
B46: Transfusion Medicine | C46: =IFERROR(AVERAGEIFS('Master Audit Tool'!M5:M67,'Master Audit Tool'!D5:D67,B46,'Master Audit Tool'!M5:M67,">0"),0) -> 0
B48: Domain Risk Heatmap
B49: Domain | C49: Avg Risk Score
B50: Quality Management System | C50: =IFERROR(AVERAGEIFS('Master Audit Tool'!M5:M151,'Master Audit Tool'!D5:D151,B50,'Master Audit Tool'!M5:M151,">0"),0) -> 0
...

Sheet Assessment Setup
B2: ASSESSMENT SETUP
B4: Field | C4: Value
B5: Organization Name
B6: Laboratory / Site Name
B7: Laboratory Director
B8: Quality Manager
B9: Assessment Date
B10: Assessor Name
B11: Target Accreditation Standard(s) | C11: ISO 15189 / CAP / JCI / AABB
B12: Laboratory Scope
B13: Number of Staff
B14: Number of Departments/Sections
B15: Previous Accreditation Date
B16: Next Survey Date
B18: DOMAIN WEIGHTS (for weighted readiness score)
B20: Domain | C20: Weight (%)
B21: Quality Management System | C21: 8.3
B22: Document Control | C22: 8.3
B23: Personnel Competency | C23: 8.3
B24: Equipment & Instrumentation | C24: 8.3
B25: Method Validation & Verification | C25: 8.3
B26: Sample Management | C26: 8.3
B27: Examination Procedures | C27: 8.3
B28: Quality Control | C28: 8.3
B29: External Quality Assessment (PT/EQA) | C29: 8.3
B30: Information Management (LIS) | C30: 8.3
B31: Facility & Safety | C31: 8.3
B32: Transfusion Medicine | C32: 8.3
B33: TOTAL | C33: =SUM(C21:C32) -> 99.6

Sheet Master Audit Tool
B2: MASTER AUDIT TOOL — COMPLIANCE ASSESSMENT
B4: Gap ID | C4: Phase | D4: Domain | E4: Requirement Area | F4: Audit Question | G4: Applicable Standard(s) | H4: Evidence Expected | I4: Status | J4: Score | K4: Severity | L4: Likelihood | M4: Risk Score | N4: Owner | O4: Due Date | P4: Notes
B5: GAP-001 | C5: Assess | D5: Quality Management System | E5: QMS Design | F5: Is there a documented quality management system (QMS) covering all laboratory activities? | G5: ISO 15189, CAP, JCI | H5: Quality manual, QMS policy documents | J5: =IF(I5="Compliant",1,IF(I5="Partial",0.5,IF(I5="Non-Compliant",0,""))) | M5: =IF(OR(K5="",L5=""),"",IFERROR(VLOOKUP(K5,'Lists & Calculations'!$F$2:$G$5,2,FALSE())*VLOOKUP(L5,'Lists & Calculations'!$I$2:$J$6,2,FALSE()),""))
B6: GAP-002 | C6: Assess | D6: Quality Management System | E6: Quality Policy | F6: Is there a quality policy signed by laboratory leadership and communicated to all staff? | G6: ISO 15189, CAP, JCI | H6: Signed quality policy document | J6: =IF(I6="Compliant",1,IF(I6="Partial",0.5,IF(I6="Non-Compliant",0,""))) | M6: =IF(OR(K6="",L6=""),"",IFERROR(VLOOKUP(K6,'Lists & Calculations'!$F$2:$G$5,2,FALSE())*VLOOKUP(L6,'Lists & Calculations'!$I$2:$J$6,2,FALSE()),""))
B7: GAP-003 | C7: Assess | D7: Quality Management System | E7: Quality Objectives | F7: Are measurable quality objectives established, monitored, and reviewed at defined intervals? | G7: ISO 15189, CAP | H7: Quality objectives document with KPIs | J7: =IF(I7="Compliant",1,IF(I7="Partial",0.5,IF(I7="Non-Compliant",0,""))) | M7: =IF(OR(K7="",L7=""),"",IFERROR(VLOOKUP(K7,'Lists & Calculations'!$F$2:$G$5,2,FALSE())*VLOOKUP(L7,'Lists & Calculations'!$I$2:$J$6,2,FALSE()),""))
B8: GAP-004 | C8: Assess | D8: Quality Management System | E8: Organizational Structure | F8: Is the laboratory organizational structure defined with clear roles and responsibilities? | G8: ISO 15189, CAP, JCI | H8: Organizational chart, job descriptions | J8: =IF(I8="Compliant",1,IF(I8="Partial",0.5,IF(I8="Non-Compliant",0,""))) | M8: =IF(OR(K8="",L8=""),"",IFERROR(VLOOKUP(K8,'Lists & Calculations'!$F$2:$G$5,2,FALSE())*VLOOKUP(L8,'Lists & Calculations'!$I$2:$J$6,2,FALSE()),""))
B9: GAP-005 | C9: Assess | D9: Quality Management System | E9: Leadership Commitment | F9: Is there evidence of leadership commitment to quality (resource allocation, management engagement)? | G9: ISO 15189, CAP, JCI | H9: Management meeting minutes, resource allocation records | J9: =IF(I9="Compliant",1,IF(I9="Partial",0.5,IF(I9="Non-Compliant",0,""))) | M9: =IF(OR(K9="",L9=""),"",IFERROR(VLOOKUP(K9,'Lists & Calculations'!$F$2:$G$5,2,FALSE())*VLOOKUP(L9,'Lists & Calculations'!$I$2:$J$6,2,FALSE()),""))
B10: GAP-006 | C10: Assess | D10: Quality Management System | E10: QMS Scope | F10: Does the QMS scope cover all laboratory activities including point-of-care testing if applicable? | G10: ISO 15189, CAP | H10: Scope statement in quality manual | J10: =IF(I10="Compliant",1,IF(I10="Partial",0.5,IF(I10="Non-Compliant",0,""))) | M10: =IF(OR(K10="",L10=""),"",IFERROR(VLOOKUP(K10,'Lists & Calculations'!$F$2:$G$5,2,FALSE())*VLOOKUP(L10,'Lists & Calculations'!$I$2:$J$6,2,FALSE()),""))
B11: GAP-007 | C11: Assess | D11: Quality Management System | E11: Continual Improvement | F11: Is there a documented process for continual improvement of the QMS? | G11: ISO 15189, CAP | H11: Improvement process procedure, improvement log | J11: =IF(I11="Compliant",1,IF(I11="Partial",0.5,IF(I11="Non-Compliant",0,""))) | M11: =IF(OR(K11="",L11=""),"",IFERROR(VLOOKUP(K11,'Lists & Calculations'!$F$2:$G$5,2,FALSE())*VLOOKUP(L11,'Lists & Calculations'!$I$2:$J$6,2,FALSE()),""))
B12: GAP-008 | C12: Assess | D12: Quality Management System | E12: Risk Management | F12: Is there a documented risk management process integrated into QMS activities? | G12: ISO 15189, CAP, JCI | H12: Risk management procedure, risk register | J12: =IF(I12="Compliant",1,IF(I12="Partial",0.5,IF(I12="Non-Compliant",0,""))) | M12: =IF(OR(K12="",L12=""),"",IFERROR(VLOOKUP(K12,'Lists & Calculations'!$F$2:$G$5,2,FALSE())*VLOOKUP(L12,'Lists & Calculations'!$I$2:$J$6,2,FALSE()),""))
B13: GAP-009 | C13: Assess | D13: Quality Management System | E13: Ethical Conduct | F13: Is there a documented code of conduct or ethics policy for laboratory personnel? | G13: ISO 15189, JCI | H13: Code of conduct document | J13: =IF(I13="Compliant",1,IF(I13="Partial",0.5,IF(I13="Non-Compliant",0,""))) | M13: =IF(OR(K13="",L13=""),"",IFERROR(VLOOKUP(K13,'Lists & Calculations'!$F$2:$G$5,2,FALSE())*VLOOKUP(L13,'Lists & Calculations'!$I$2:$J$6,2,FALSE()),""))
B14: GAP-010 | C14: Assess | D14: Quality Management System | E14: Conflict of Interest | F14: Are conflict of interest declarations maintained for all laboratory personnel? | G14: ISO 15189, CAP | H14: Conflict of interest declarations | J14: =IF(I14="Compliant",1,IF(I14="Partial",0.5,IF(I14="Non-Compliant",0,""))) | M14: =IF(OR(K14="",L14=""),"",IFERROR(VLOOKUP(K14,'Lists & Calculations'!$F$2:$G$5,2,FALSE())*VLOOKUP(L14,'Lists & Calculations'!$I$2:$J$6,2,FALSE()),""))
B15: GAP-011 | C15: Assess | D15: Document Control | E15: SOP Management | F15: Are all laboratory procedures documented in controlled SOPs with version control? | G15: ISO 15189, CAP, JCI, AABB | H15: SOP register, version-controlled documents | J15: =IF(I15="Compliant",1,IF(I15="Partial",0.5,IF(I15="Non-Compliant",0,""))) | M15: =IF(OR(K15="",L15=""),"",IFERROR(VLOOKUP(K15,'Lists & Calculations'!$F$2:$G$5,2,FALSE())*VLOOKUP(L15,'Lists & Calculations'!$I$2:$J$6,2,FALSE()),""))
B16: GAP-012 | C16: Assess | D16: Document Control | E16: Document Approval | F16: Are documents reviewed and approved by authorized personnel before implementation? | G16: ISO 15189, CAP | H16: Approval signatures, document control log | J16: =IF(I16="Compliant",1,IF(I16="Partial",0.5,IF(I16="Non-Compliant",0,""))) | M16: =IF(OR(K16="",L16=""),"",IFERROR(VLOOKUP(K16,'Lists & Calculations'!$F$2:$G$5,2,FALSE())*VLOOKUP(L16,'Lists & Calculations'!$I$2:$J$6,2,FALSE()),""))
... B151: GAP-147 | C151: Assess | D151: Outreach & Customer Service | E151: Client Satisfaction | F151: Is client satisfaction monitored and reviewed? | G151: ISO 15189, CAP | H151: Client satisfaction survey results | J151: =IF(I151="Compliant",1,IF(I151="Partial",0.5,IF(I151="Non-Compliant",0,""))) | M151: =IF(OR(K151="",L151=""),"",IFERROR(VLOOKUP(K151,'Lists & Calculations'!$F$2:$G$5,2,FALSE())*VLOOKUP(L151,'Lists & Calculations'!$I$2:$J$6,2,FALSE()),""))
B153: SUMMARY
B154: Total Items: | C154: =COUNTA(B5:B151) -> 147
B155: Compliant: | C155: =COUNTIF(I5:I151,"Compliant") -> 0
B156: Partial: | C156: =COUNTIF(I5:I151,"Partial") -> 0
B157: Non-Compliant: | C157: =COUNTIF(I5:I151,"Non-Compliant") -> 0
B158: Overall Readiness %: | C158: =IFERROR(AVERAGEIF(J5:J151,">=0"),"")

Sheet Gap Register
B2: GAP REGISTER
B4: Gap ID | C4: Source Audit Item | D4: Domain | E4: Gap Description | F4: Evidence Missing | G4: Severity | H4: Likelihood | I4: Risk Priority | J4: Immediate Containment | K4: Owner | L4: Target Date | M4: Status
B5: GAP-001 | I5: =IF(AND(G5<>"",H5<>""),VLOOKUP(G5,'Lists & Calculations'!$F$2:$G$5,2,FALSE())*VLOOKUP(H5,'Lists & Calculations'!$I$2:$J$6,2,FALSE()),"")
B6: GAP-002 | I6: =IF(AND(G6<>"",H6<>""),VLOOKUP(G6,'Lists & Calculations'!$F$2:$G$5,2,FALSE())*VLOOKUP(H6,'Lists & Calculations'!$I$2:$J$6,2,FALSE()),"")
B7: GAP-003 | I7: =IF(AND(G7<>"",H7<>""),VLOOKUP(G7,'Lists & Calculations'!$F$2:$G$5,2,FALSE())*VLOOKUP(H7,'Lists & Calculations'!$I$2:$J$6,2,FALSE()),"")
B8: GAP-004 | I8: =IF(AND(G8<>"",H8<>""),VLOOKUP(G8,'Lists & Calculations'!$F$2:$G$5,2,FALSE())*VLOOKUP(H8,'Lists & Calculations'!$I$2:$J$6,2,FALSE()),"")
B9: GAP-005 | I9: =IF(AND(G9<>"",H9<>""),VLOOKUP(G9,'Lists & Calculations'!$F$2:$G$5,2,FALSE())*VLOOKUP(H9,'Lists & Calculations'!$I$2:$J$6,2,FALSE()),"")
B10: GAP-006 | I10: =IF(AND(G10<>"",H10<>""),VLOOKUP(G10,'Lists & Calculations'!$F$2:$G$5,2,FALSE())*VLOOKUP(H10,'Lists & Calculations'!$I$2:$J$6,2,FALSE()),"")
B11: GAP-007 | I11: =IF(AND(G11<>"",H11<>""),VLOOKUP(G11,'Lists & Calculations'!$F$2:$G$5,2,FALSE())*VLOOKUP(H11,'Lists & Calculations'!$I$2:$J$6,2,FALSE()),"")
B12: GAP-008 | I12: =IF(AND(G12<>"",H12<>""),VLOOKUP(G12,'Lists & Calculations'!$F$2:$G$5,2,FALSE())*VLOOKUP(H12,'Lists & Calculations'!$I$2:$J$6,2,FALSE()),"")
B13: GAP-009 | I13: =IF(AND(G13<>"",H13<>""),VLOOKUP(G13,'Lists & Calculations'!$F$2:$G$5,2,FALSE())*VLOOKUP(H13,'Lists & Calculations'!$I$2:$J$6,2,FALSE()),"")
B14: GAP-010 | I14: =IF(AND(G14<>"",H14<>""),VLOOKUP(G14,'Lists & Calculations'!$F$2:$G$5,2,FALSE())*VLOOKUP(H14,'Lists & Calculations'!$I$2:$J$6,2,FALSE()),"")
B15: GAP-011 | I15: =IF(AND(G15<>"",H15<>""),VLOOKUP(G15,'Lists & Calculations'!$F$2:$G$5,2,FALSE())*VLOOKUP(H15,'Lists & Calculations'!$I$2:$J$6,2,FALSE()),"")
B16: GAP-012 | I16: =IF(AND(G16<>"",H16<>""),VLOOKUP(G16,'Lists & Calculations'!$F$2:$G$5,2,FALSE())*VLOOKUP(H16,'Lists & Calculations'!$I$2:$J$6,2,FALSE()),"")
... B54: GAP-050 | I54: =IF(AND(G54<>"",H54<>""),VLOOKUP(G54,'Lists & Calculations'!$F$2:$G$5,2,FALSE())*VLOOKUP(H54,'Lists & Calculations'!$I$2:$J$6,2,FALSE()),"")

Sheet CAPA Action Plan
B2: CAPA ACTION PLAN — CORRECTIVE & PREVENTIVE ACTIONS
B4: CAPA ID | C4: Gap ID | D4: Domain | E4: Nonconformity Description | F4: Root Cause | G4: Corrective Action | H4: Preventive Action | I4: Owner | J4: Target Date | K4: Status | L4: Overdue? | M4: Effectiveness Check | N4: Verification Date | O4: Notes
B5: CAPA-001 | L5: =IF(AND(J5<>"",K5<>"",K5<>"Complete",K5<>"Verified",J5<TODAY()),"OVERDUE","")
B6: CAPA-002 | L6: =IF(AND(J6<>"",K6<>"",K6<>"Complete",K6<>"Verified",J6<TODAY()),"OVERDUE","")
B7: CAPA-003 | L7: =IF(AND(J7<>"",K7<>"",K7<>"Complete",K7<>"Verified",J7<TODAY()),"OVERDUE","")
B8: CAPA-004 | L8: =IF(AND(J8<>"",K8<>"",K8<>"Complete",K8<>"Verified",J8<TODAY()),"OVERDUE","")
B9: CAPA-005 | L9: =IF(AND(J9<>"",K9<>"",K9<>"Complete",K9<>"Verified",J9<TODAY()),"OVERDUE","")
B10: CAPA-006 | L10: =IF(AND(J10<>"",K10<>"",K10<>"Complete",K10<>"Verified",J10<TODAY()),"OVERDUE","")
B11: CAPA-007 | L11: =IF(AND(J11<>"",K11<>"",K11<>"Complete",K11<>"Verified",J11<TODAY()),"OVERDUE","")
B12: CAPA-008 | L12: =IF(AND(J12<>"",K12<>"",K12<>"Complete",K12<>"Verified",J12<TODAY()),"OVERDUE","")
B13: CAPA-009 | L13: =IF(AND(J13<>"",K13<>"",K13<>"Complete",K13<>"Verified",J13<TODAY()),"OVERDUE","")
B14: CAPA-010 | L14: =IF(AND(J14<>"",K14<>"",K14<>"Complete",K14<>"Verified",J14<TODAY()),"OVERDUE","")
B15: CAPA-011 | L15: =IF(AND(J15<>"",K15<>"",K15<>"Complete",K15<>"Verified",J15<TODAY()),"OVERDUE","")
B16: CAPA-012 | L16: =IF(AND(J16<>"",K16<>"",K16<>"Complete",K16<>"Verified",J16<TODAY()),"OVERDUE","")
... B54: CAPA-050 | L54: =IF(AND(J54<>"",K54<>"",K54<>"Complete",K54<>"Verified",J54<TODAY()),"OVERDUE","")

Sheet Evidence Tracker
B2: EVIDENCE TRACKER — DOCUMENT & RECORD INVENTORY
B4: Evidence ID | C4: Evidence Item | D4: Domain | E4: Related Standard | F4: Location/Link | G4: Owner | H4: Status | I4: Last Reviewed | J4: Notes
B5: EV-001
B6: EV-002
B7: EV-003
B8: EV-004
B9: EV-005
B10: EV-006
B11: EV-007
B12: EV-008
B13: EV-009
B14: EV-010
B15: EV-011
B16: EV-012
... B64: EV-060

Sheet Competency & Training
B2: COMPETENCY & TRAINING TRACKER
B4: Staff ID | C4: Name | D4: Role/Title | E4: Section/Department | F4: Qualification | G4: Initial Competency | H4: Annual Competency | I4: Direct Observation | J4: Continuing Education (hrs) | K4: Status | L4: Notes
B5: STAFF-001
B6: STAFF-002
B7: STAFF-003
B8: STAFF-004
B9: STAFF-005
B10: STAFF-006
B11: STAFF-007
B12: STAFF-008
B13: STAFF-009
B14: STAFF-010
B15: STAFF-011
B16: STAFF-012
... B29: STAFF-025

Sheet Equipment, QC & PT
B2: EQUIPMENT, QC & PROFICIENCY TESTING TRACKER
B4: Equipment ID | C4: Equipment Name | D4: Serial Number | E4: Section/Department | F4: Calibration Due | G4: Maintenance Due | H4: QC Daily Review | I4: PT/EQA Provider | J4: PT Status | K4: Last PT Date | L4: PT Result | M4: Notes
B5: EQ-001
B6: EQ-002
B7: EQ-003
B8: EQ-004
B9: EQ-005
B10: EQ-006
B11: EQ-007
B12: EQ-008
B13: EQ-009
B14: EQ-010
B15: EQ-011
B16: EQ-012
... B34: EQ-030

Sheet Document Control
B2: DOCUMENT CONTROL REGISTER
B4: Document ID | C4: Document Title | D4: Type | E4: Version | F4: Section/Department | G4: Author | H4: Approved By | I4: Review Date | J4: Status | K4: Notes
B5: DOC-001
B6: DOC-002
B7: DOC-003
B8: DOC-004
B9: DOC-005
B10: DOC-006
B11: DOC-007
B12: DOC-008
B13: DOC-009
B14: DOC-010
B15: DOC-011
B16: DOC-012
... B44: DOC-040

Sheet Internal Audit & Tracer
B2: INTERNAL AUDIT & TRACER PLAN
B4: Audit ID | C4: Audit Date | D4: Area/Process | E4: Auditor | F4: Documents Sampled | G4: Staff Interviewed | H4: Findings | I4: Risk Level | J4: Action Required | K4: Follow-up Date | L4: Notes
B5: IA-001
B6: IA-002
B7: IA-003
B8: IA-004
B9: IA-005
B10: IA-006
B11: IA-007
B12: IA-008
B13: IA-009
B14: IA-010
B15: IA-011
B16: IA-012
... B29: IA-025

Sheet Mgmt Review & Sustain
B2: MANAGEMENT REVIEW & SUSTAIN TRACKER
B4: MANAGEMENT REVIEW AGENDA ITEMS
B5: Item | C5: Review Topic | D5: Input Required | E5: Responsible | F5: Status | G5: Actions/Decisions | H5: Follow-up Date
B6: MR-001 | C6: Audit results (internal & external) | D6: Internal audit reports, external assessment findings
B7: MR-002 | C7: Quality indicators & KPIs | D7: KPI dashboard, trend analysis
B8: MR-003 | C8: CAPA status & effectiveness | D8: CAPA register, effectiveness check results
B9: MR-004 | C9: PT/EQA results | D9: Proficiency testing reports
B10: MR-005 | C10: Complaints & feedback | D10: Complaint log, patient feedback
B11: MR-006 | C11: Personnel competency | D11: Competency assessment records
B12: MR-007 | C12: Equipment & facility status | D12: Equipment maintenance, facility inspection
B13: MR-008 | C13: Document & record review | D13: Document control register
B14: MR-009 | C14: Risk assessment update | D14: Risk register, risk assessment
B15: MR-010 | C15: Improvement opportunities | D15: Improvement suggestions, projects
B16: MR-011 | C16: Previous review actions | D16: Previous management review minutes
B17: MR-012 | C17: Resource needs | D17: Staffing, equipment, facility needs
B20: QUALITY INDICATORS & KPIs
B21: KPI ID | C21: Indicator | D21: Target | E21: Current Value | F21: Status | G21: Trend | H21: Notes
B22: KPI-001 | C22: Turnaround Time - Routine | D22: ≤ 4 hours
B23: KPI-002 | C23: Turnaround Time - STAT | D23: ≤ 1 hour
B24: KPI-003 | C24: Sample Rejection Rate | D24: ≤ 2%
B25: KPI-004 | C25: Critical Value Reporting Time | D25: ≤ 30 minutes
B26: KPI-005 | C26: PT/EQA Pass Rate | D26: 100%
B27: KPI-006 | C27: Document Review Compliance | D27: 100%
B28: KPI-007 | C28: Competency Assessment Completion | D28: 100%
B29: KPI-008 | C29: CAPA Closure Rate | D29: ≥ 90%
B30: KPI-009 | C30: Equipment Calibration Compliance | D30: 100%
B31: KPI-010 | C31: Internal Audit Schedule Compliance | D31: ≥ 95%

Sheet Standards Crosswalk
B2: STANDARDS CROSSWALK — DOMAIN MAPPING
B4: Domain | C4: ISO 15189 Relevance | D4: CAP Relevance | E4: JCI Relevance | F4: AABB Relevance | G4: Notes
B5: Quality Management System | C5: Clauses 4-8: QMS requirements | D5: CAP All Common Checklist | E5: GLD.1, GLD.2 | F5: AABB QMS requirements
B6: Document Control | C6: Clause 8.4: Document control | D6: CAP document control requirements | E6: GLD.1.1, GLD.1.2 | F6: AABB document control
B7: Personnel Competency | C7: Clause 6.2: Personnel | D7: CAP personnel requirements | E7: SQE.1, SQE.2 | F7: AABB personnel competency
B8: Equipment & Instrumentation | C8: Clause 7.1: Equipment | D8: CAP equipment requirements | E8: FMS.8 | F8: AABB equipment
B9: Method Validation | C9: Clause 7.2: Validation | D9: CAP method validation | E9: — | F9: —
B10: Sample Management | C10: Clause 7.2: Pre-examination | D10: CAP pre-analytical | E10: PFR.1 | F10: AABB sample management
B11: Quality Control | C11: Clause 7.3: Quality control | D11: CAP QC requirements | E11: QPS.3 | F11: AABB QC
B12: PT/EQA | C12: Clause 7.3: External QC | D12: CAP PT requirements | E12: QPS.2 | F12: AABB PT/EQA
B13: Information Management | C13: Clause 8: Information management | D13: CAP LIS requirements | E13: GLD.3 | F13: —
B14: Facility & Safety | C14: Clause 7.1.4: Environment | D14: CAP safety requirements | E14: FMS.1-FMS.7 | F14: AABB safety
B15: Transfusion Medicine | C15: Clause 7.2: Transfusion | D15: CAP transfusion | E15: — | F15: AABB transfusion
B16: CAPA & RCA | C16: Clause 7.10: Nonconforming work | D16: CAP CAPA requirements | E16: QPS.7 | F16: AABB CAPA
... B22: Outreach & Customer Service | C22: Clause 8.7: Communication | D22: CAP client communication | E22: — | F22: AABB communication

Sheet Lists & Calculations
B1: STATUS_OPTIONS | C1: SCORE_MAP | E1: SEVERITY_OPTIONS | F1: SEV_SCORE | H1: LIKELIHOOD_OPTIONS | I1: LIKE_SCORE | K1: PHASE_OPTIONS | L1: DOMAIN_OPTIONS | N1: CAPA_STATUS | O1: EVIDENCE_STATUS
B2: Compliant | C2: Compliant | D2: 1 | E2: Critical | F2: Critical | G2: 5 | H2: Almost Certain | I2: Almost Certain | J2: 5 | K2: Assess | L2: Quality Management System | N2: Not Started | O2: Current
B3: Partial | C3: Partial | D3: 0.5 | E3: High | F3: High | G3: 4 | H3: Likely | I3: Likely | J3: 4 | K3: Prioritize | L3: Document Control | N3: In Progress | O3: Needs Update
B4: Non-Compliant | C4: Non-Compliant | D4: 0 | E4: Medium | F4: Medium | G4: 3 | H4: Possible | I4: Possible | J4: 3 | K4: Improve | L4: Personnel Competency | N4: Complete | O4: Missing
B5: Not Applicable | C5: Not Applicable | D5: N/A | E5: Low | F5: Low | G5: 2 | H5: Unlikely | I5: Unlikely | J5: 2 | K5: Sustain | L5: Equipment & Instrumentation | N5: Verified
H6: Rare | I6: Rare | J6: 1 | L6: Method Validation & Verification | N6: Overdue
L7: Sample Management
L8: Examination Procedures
L9: Quality Control
L10: External Quality Assessment (PT/EQA)
L11: Information Management (LIS)
L12: Facility & Safety
L13: Transfusion Medicine
L14: CAPA & Root Cause Analysis
L15: Internal Audit
L16: Management Review
L17: Pre-analytical Phase
L18: Analytical Phase
... L25: Outreach & Customer Service

Sheet Sources & Disclaimer
B2: SOURCES & DISCLAIMER
B4: STANDARDS REFERENCED
B5: • ISO 15189:2022 — Medical laboratories — Requirements for quality and competence (general concepts only)
B6: • CAP Accreditation Program — College of American Pathologists (public framework information)
B7: • JCI Accreditation Standards for Hospitals — Joint Commission International (public framework information)
B8: • AABB Standards — Association for the Advancement of Blood & Biotherapies (public framework information)
B10: DISCLAIMER
B11: This toolkit is an independent readiness preparation tool provided by AHQS (Accelerate Healthcare Quality Solutions). It does not reproduce proprietary accreditation standard text. Audit questions are general readiness prompts based on publicly available concepts from ISO 15189, CAP, JCI, and AABB frameworks. This toolkit does not constitute accreditation, certification, legal advice, or a guarantee of accreditation outcomes. Accreditation and certification decisions remain with the applicable authorized organizations. Users should refer to the official standards documents published by the respective accreditation bodies for complete and current requirements. AHQS provides independent quality-improvement and accreditation-readiness consulting. Use of this toolkit does not create a consulting engagement. Any paid engagement begins only after a written scope, timeline, and professional fee proposal has been approved.
B14: © 2026 Accelerate Healthcare Quality Solutions (AHQS). All rights reserved.
B15: Contact: info@ahqshealthcare.com | +1 (984) 317-3711 | ahqshealthcare.com
